2020-09-25 13:30:16,957 (util.py:68 PollingThread) ERROR - TeleBot: "ReadTimeout occurred, args=(ReadTimeoutError("HTTPSConnectionPool(host='api.telegram.org', port=443): Read timed out. (read timeout=30)"),)
Traceback (most recent call last):
  File "C:\Users\Administrator\AppData\Local\Programs\Python\Python37-32\lib\site-packages\urllib3\connectionpool.py", line 426, in _make_request
    six.raise_from(e, None)
  File "<string>", line 3, in raise_from
  File "C:\Users\Administrator\AppData\Local\Programs\Python\Python37-32\lib\site-packages\urllib3\connectionpool.py", line 421, in _make_request
    httplib_response = conn.getresponse()
  File "C:\Users\Administrator\AppData\Local\Programs\Python\Python37-32\lib\http\client.py", line 1321, in getresponse
    response.begin()
  File "C:\Users\Administrator\AppData\Local\Programs\Python\Python37-32\lib\http\client.py", line 296, in begin
    version, status, reason = self._read_status()
  File "C:\Users\Administrator\AppData\Local\Programs\Python\Python37-32\lib\http\client.py", line 257, in _read_status
    line = str(self.fp.readline(_MAXLINE + 1), "iso-8859-1")
  File "C:\Users\Administrator\AppData\Local\Programs\Python\Python37-32\lib\socket.py", line 589, in readinto
    return self._sock.recv_into(b)
  File "C:\Users\Administrator\AppData\Local\Programs\Python\Python37-32\lib\ssl.py", line 1052, in recv_into
    return self.read(nbytes, buffer)
  File "C:\Users\Administrator\AppData\Local\Programs\Python\Python37-32\lib\ssl.py", line 911, in read
    return self._sslobj.read(len, buffer)
socket.timeout: The read operation timed out

During handling of the above exception, another exception occurred:

Traceback (most recent call last):
  File "C:\Users\Administrator\AppData\Local\Programs\Python\Python37-32\lib\site-packages\requests\adapters.py", line 449, in send
    timeout=timeout
  File "C:\Users\Administrator\AppData\Local\Programs\Python\Python37-32\lib\site-packages\urllib3\connectionpool.py", line 727, in urlopen
    method, url, error=e, _pool=self, _stacktrace=sys.exc_info()[2]
  File "C:\Users\Administrator\AppData\Local\Programs\Python\Python37-32\lib\site-packages\urllib3\util\retry.py", line 403, in increment
    raise six.reraise(type(error), error, _stacktrace)
  File "C:\Users\Administrator\AppData\Local\Programs\Python\Python37-32\lib\site-packages\urllib3\packages\six.py", line 735, in reraise
    raise value
  File "C:\Users\Administrator\AppData\Local\Programs\Python\Python37-32\lib\site-packages\urllib3\connectionpool.py", line 677, in urlopen
    chunked=chunked,
  File "C:\Users\Administrator\AppData\Local\Programs\Python\Python37-32\lib\site-packages\urllib3\connectionpool.py", line 428, in _make_request
    self._raise_timeout(err=e, url=url, timeout_value=read_timeout)
  File "C:\Users\Administrator\AppData\Local\Programs\Python\Python37-32\lib\site-packages\urllib3\connectionpool.py", line 336, in _raise_timeout
    self, url, "Read timed out. (read timeout=%s)" % timeout_value
urllib3.exceptions.ReadTimeoutError: HTTPSConnectionPool(host='api.telegram.org', port=443): Read timed out. (read timeout=30)

During handling of the above exception, another exception occurred:

Traceback (most recent call last):
  File "C:\Users\Administrator\AppData\Local\Programs\Python\Python37-32\lib\site-packages\telebot\util.py", line 62, in run
    task(*args, **kwargs)
  File "C:\Users\Administrator\AppData\Local\Programs\Python\Python37-32\lib\site-packages\telebot\__init__.py", line 285, in __retrieve_updates
    updates = self.get_updates(offset=(self.last_update_id + 1), timeout=timeout)
  File "C:\Users\Administrator\AppData\Local\Programs\Python\Python37-32\lib\site-packages\telebot\__init__.py", line 255, in get_updates
    json_updates = apihelper.get_updates(self.token, offset, limit, timeout, allowed_updates)
  File "C:\Users\Administrator\AppData\Local\Programs\Python\Python37-32\lib\site-packages\telebot\apihelper.py", line 206, in get_updates
    return _make_request(token, method_url, params=payload)
  File "C:\Users\Administrator\AppData\Local\Programs\Python\Python37-32\lib\site-packages\telebot\apihelper.py", line 67, in _make_request
    timeout=(connect_timeout, read_timeout), proxies=proxy)
  File "C:\Users\Administrator\AppData\Local\Programs\Python\Python37-32\lib\site-packages\requests\sessions.py", line 530, in request
    resp = self.send(prep, **send_kwargs)
  File "C:\Users\Administrator\AppData\Local\Programs\Python\Python37-32\lib\site-packages\requests\sessions.py", line 643, in send
    r = adapter.send(request, **kwargs)
  File "C:\Users\Administrator\AppData\Local\Programs\Python\Python37-32\lib\site-packages\requests\adapters.py", line 529, in send
    raise ReadTimeout(e, request=request)
requests.exceptions.ReadTimeout: HTTPSConnectionPool(host='api.telegram.org', port=443): Read timed out. (read timeout=30)
"
Traceback (most recent call last):
  File "C:\Users\Administrator\AppData\Local\Programs\Python\Python37-32\lib\site-packages\urllib3\connectionpool.py", line 426, in _make_request
    six.raise_from(e, None)
  File "<string>", line 3, in raise_from
  File "C:\Users\Administrator\AppData\Local\Programs\Python\Python37-32\lib\site-packages\urllib3\connectionpool.py", line 421, in _make_request
    httplib_response = conn.getresponse()
  File "C:\Users\Administrator\AppData\Local\Programs\Python\Python37-32\lib\http\client.py", line 1321, in getresponse
    response.begin()
  File "C:\Users\Administrator\AppData\Local\Programs\Python\Python37-32\lib\http\client.py", line 296, in begin
    version, status, reason = self._read_status()
  File "C:\Users\Administrator\AppData\Local\Programs\Python\Python37-32\lib\http\client.py", line 257, in _read_status
    line = str(self.fp.readline(_MAXLINE + 1), "iso-8859-1")
  File "C:\Users\Administrator\AppData\Local\Programs\Python\Python37-32\lib\socket.py", line 589, in readinto
    return self._sock.recv_into(b)
  File "C:\Users\Administrator\AppData\Local\Programs\Python\Python37-32\lib\ssl.py", line 1052, in recv_into
    return self.read(nbytes, buffer)
  File "C:\Users\Administrator\AppData\Local\Programs\Python\Python37-32\lib\ssl.py", line 911, in read
    return self._sslobj.read(len, buffer)
socket.timeout: The read operation timed out

During handling of the above exception, another exception occurred:

Traceback (most recent call last):
  File "C:\Users\Administrator\AppData\Local\Programs\Python\Python37-32\lib\site-packages\requests\adapters.py", line 449, in send
    timeout=timeout
  File "C:\Users\Administrator\AppData\Local\Programs\Python\Python37-32\lib\site-packages\urllib3\connectionpool.py", line 727, in urlopen
    method, url, error=e, _pool=self, _stacktrace=sys.exc_info()[2]
  File "C:\Users\Administrator\AppData\Local\Programs\Python\Python37-32\lib\site-packages\urllib3\util\retry.py", line 403, in increment
    raise six.reraise(type(error), error, _stacktrace)
  File "C:\Users\Administrator\AppData\Local\Programs\Python\Python37-32\lib\site-packages\urllib3\packages\six.py", line 735, in reraise
    raise value
  File "C:\Users\Administrator\AppData\Local\Programs\Python\Python37-32\lib\site-packages\urllib3\connectionpool.py", line 677, in urlopen
    chunked=chunked,
  File "C:\Users\Administrator\AppData\Local\Programs\Python\Python37-32\lib\site-packages\urllib3\connectionpool.py", line 428, in _make_request
    self._raise_timeout(err=e, url=url, timeout_value=read_timeout)
  File "C:\Users\Administrator\AppData\Local\Programs\Python\Python37-32\lib\site-packages\urllib3\connectionpool.py", line 336, in _raise_timeout
    self, url, "Read timed out. (read timeout=%s)" % timeout_value
urllib3.exceptions.ReadTimeoutError: HTTPSConnectionPool(host='api.telegram.org', port=443): Read timed out. (read timeout=30)

During handling of the above exception, another exception occurred:

Traceback (most recent call last):
  File "main.py", line 147, in <module>
    bot.polling()
  File "C:\Users\Administrator\AppData\Local\Programs\Python\Python37-32\lib\site-packages\telebot\__init__.py", line 427, in polling
    self.__threaded_polling(none_stop, interval, timeout)
  File "C:\Users\Administrator\AppData\Local\Programs\Python\Python37-32\lib\site-packages\telebot\__init__.py", line 450, in __threaded_polling
    polling_thread.raise_exceptions()
  File "C:\Users\Administrator\AppData\Local\Programs\Python\Python37-32\lib\site-packages\telebot\util.py", line 81, in raise_exceptions
    six.reraise(self.exc_info[0], self.exc_info[1], self.exc_info[2])
  File "C:\Users\Administrator\AppData\Local\Programs\Python\Python37-32\lib\site-packages\six.py", line 703, in reraise
    raise value
  File "C:\Users\Administrator\AppData\Local\Programs\Python\Python37-32\lib\site-packages\telebot\util.py", line 62, in run
    task(*args, **kwargs)
  File "C:\Users\Administrator\AppData\Local\Programs\Python\Python37-32\lib\site-packages\telebot\__init__.py", line 285, in __retrieve_updates
    updates = self.get_updates(offset=(self.last_update_id + 1), timeout=timeout)
  File "C:\Users\Administrator\AppData\Local\Programs\Python\Python37-32\lib\site-packages\telebot\__init__.py", line 255, in get_updates
    json_updates = apihelper.get_updates(self.token, offset, limit, timeout, allowed_updates)
  File "C:\Users\Administrator\AppData\Local\Programs\Python\Python37-32\lib\site-packages\telebot\apihelper.py", line 206, in get_updates
    return _make_request(token, method_url, params=payload)
  File "C:\Users\Administrator\AppData\Local\Programs\Python\Python37-32\lib\site-packages\telebot\apihelper.py", line 67, in _make_request
    timeout=(connect_timeout, read_timeout), proxies=proxy)
  File "C:\Users\Administrator\AppData\Local\Programs\Python\Python37-32\lib\site-packages\requests\sessions.py", line 530, in request
    resp = self.send(prep, **send_kwargs)
  File "C:\Users\Administrator\AppData\Local\Programs\Python\Python37-32\lib\site-packages\requests\sessions.py", line 643, in send
    r = adapter.send(request, **kwargs)
  File "C:\Users\Administrator\AppData\Local\Programs\Python\Python37-32\lib\site-packages\requests\adapters.py", line 529, in send
    raise ReadTimeout(e, request=request)
requests.exceptions.ReadTimeout: HTTPSConnectionPool(host='api.telegram.org', port=443): Read timed out. (read timeout=30)
